2021-07-24 13:08:40,662 ERROR: Exception on /user/susan [GET] [in d:\py\microblog\venv\lib\site-packages\flask\app.py:1454]
Traceback (most recent call last):
  File "d:\py\microblog\venv\lib\site-packages\flask\app.py", line 2070, in wsgi_app
    response = self.full_dispatch_request()
  File "d:\py\microblog\venv\lib\site-packages\flask\app.py", line 1515, in full_dispatch_request
    rv = self.handle_user_exception(e)
  File "d:\py\microblog\venv\lib\site-packages\flask\app.py", line 1513, in full_dispatch_request
    rv = self.dispatch_request()
  File "d:\py\microblog\venv\lib\site-packages\flask\app.py", line 1499, in dispatch_request
    return self.ensure_sync(self.view_functions[rule.endpoint])(**req.view_args)
  File "d:\py\microblog\venv\lib\site-packages\flask_login\utils.py", line 271, in decorated_view
    return current_app.login_manager.unauthorized()
  File "d:\py\microblog\venv\lib\site-packages\flask_login\login_manager.py", line 174, in unauthorized
    redirect_url = make_login_url(login_view, next_url=request.url)
  File "d:\py\microblog\venv\lib\site-packages\flask_login\utils.py", line 120, in login_url
    base = expand_login_view(login_view)
  File "d:\py\microblog\venv\lib\site-packages\flask_login\utils.py", line 97, in expand_login_view
    return url_for(login_view)
  File "d:\py\microblog\venv\lib\site-packages\flask\helpers.py", line 338, in url_for
    return appctx.app.handle_url_build_error(error, endpoint, values)
  File "d:\py\microblog\venv\lib\site-packages\flask\helpers.py", line 325, in url_for
    rv = url_adapter.build(
  File "d:\py\microblog\venv\lib\site-packages\werkzeug\routing.py", line 2305, in build
    raise BuildError(endpoint, values, method, self)
werkzeug.routing.BuildError: Could not build url for endpoint 'main.login'. Did you mean 'auth.login' instead?
2021-07-24 13:08:58,442 INFO: Microblog startup [in D:\py\microblog\app\__init__.py:86]
