2021-08-02 10:51:46,294 INFO: Microblog startup [in /home/epaphradito/programming/py/flask/microblog/app/__init__.py:96]
2021-08-02 10:58:00,177 INFO: Microblog startup [in /home/epaphradito/programming/py/flask/microblog/app/__init__.py:96]
2021-08-02 11:04:54,183 INFO: Microblog startup [in /home/epaphradito/programming/py/flask/microblog/app/__init__.py:96]
2021-08-02 11:07:26,764 INFO: Microblog startup [in /home/epaphradito/programming/py/flask/microblog/app/__init__.py:96]
2021-08-02 11:08:11,934 ERROR: Exception on /api/user/5 [GET] [in /home/epaphradito/programming/py/flask/microblog/venv/lib/python3.8/site-packages/flask/app.py:1454]
Traceback (most recent call last):
  File "/home/epaphradito/programming/py/flask/microblog/venv/lib/python3.8/site-packages/flask/app.py", line 1513, in full_dispatch_request
    rv = self.dispatch_request()
  File "/home/epaphradito/programming/py/flask/microblog/venv/lib/python3.8/site-packages/flask/app.py", line 1489, in dispatch_request
    self.raise_routing_exception(req)
  File "/home/epaphradito/programming/py/flask/microblog/venv/lib/python3.8/site-packages/flask/app.py", line 1471, in raise_routing_exception
    raise request.routing_exception  # type: ignore
  File "/home/epaphradito/programming/py/flask/microblog/venv/lib/python3.8/site-packages/flask/ctx.py", line 367, in match_request
    result = self.url_adapter.match(return_rule=True)  # type: ignore
  File "/home/epaphradito/programming/py/flask/microblog/venv/lib/python3.8/site-packages/werkzeug/routing.py", line 2032, in match
    raise NotFound()
werkzeug.exceptions.NotFound: 404 Not Found: The requested URL was not found on the server. If you entered the URL manually please check your spelling and try again.

During handling of the above exception, another exception occurred:

Traceback (most recent call last):
  File "/home/epaphradito/programming/py/flask/microblog/venv/lib/python3.8/site-packages/flask/app.py", line 2070, in wsgi_app
    response = self.full_dispatch_request()
  File "/home/epaphradito/programming/py/flask/microblog/venv/lib/python3.8/site-packages/flask/app.py", line 1515, in full_dispatch_request
    rv = self.handle_user_exception(e)
  File "/home/epaphradito/programming/py/flask/microblog/venv/lib/python3.8/site-packages/flask/app.py", line 1383, in handle_user_exception
    return self.handle_http_exception(e)
  File "/home/epaphradito/programming/py/flask/microblog/venv/lib/python3.8/site-packages/flask/app.py", line 1323, in handle_http_exception
    return self.ensure_sync(handler)(e)
  File "/home/epaphradito/programming/py/flask/microblog/app/errors/handlers.py", line 12, in not_found_error
    if wants_json_response():
  File "/home/epaphradito/programming/py/flask/microblog/app/errors/handlers.py", line 7, in wants_json_response
    return request.accept_mimetypes['application/json'] >= \
NameError: name 'request' is not defined
2021-08-02 11:08:46,492 INFO: Microblog startup [in /home/epaphradito/programming/py/flask/microblog/app/__init__.py:96]
